[2023-06-15T14:40:51.799+0000] {taskinstance.py:1103} INFO - Dependencies all met for dep_context=non-requeueable deps ti=<TaskInstance: gcs-files-dag.GCS_Files manual__2023-06-15T14:40:50.289983+00:00 [queued]>
[2023-06-15T14:40:51.806+0000] {taskinstance.py:1103} INFO - Dependencies all met for dep_context=requeueable deps ti=<TaskInstance: gcs-files-dag.GCS_Files manual__2023-06-15T14:40:50.289983+00:00 [queued]>
[2023-06-15T14:40:51.807+0000] {taskinstance.py:1308} INFO - Starting attempt 1 of 1
[2023-06-15T14:40:51.818+0000] {taskinstance.py:1327} INFO - Executing <Task(GCSListObjectsOperator): GCS_Files> on 2023-06-15 14:40:50.289983+00:00
[2023-06-15T14:40:51.824+0000] {standard_task_runner.py:57} INFO - Started process 558 to run task
[2023-06-15T14:40:51.829+0000] {standard_task_runner.py:84} INFO - Running: ['***', 'tasks', 'run', 'gcs-files-dag', 'GCS_Files', 'manual__2023-06-15T14:40:50.289983+00:00', '--job-id', '9', '--raw', '--subdir', 'DAGS_FOLDER/gcp_test.py', '--cfg-path', '/tmp/tmpljo1c_zu']
[2023-06-15T14:40:51.832+0000] {standard_task_runner.py:85} INFO - Job 9: Subtask GCS_Files
[2023-06-15T14:40:51.887+0000] {task_command.py:410} INFO - Running <TaskInstance: gcs-files-dag.GCS_Files manual__2023-06-15T14:40:50.289983+00:00 [running]> on host 6f3c5cb11aa3
[2023-06-15T14:40:51.960+0000] {taskinstance.py:1547} INFO - Exporting env vars: AIRFLOW_CTX_DAG_OWNER='***' AIRFLOW_CTX_DAG_ID='gcs-files-dag' AIRFLOW_CTX_TASK_ID='GCS_Files' AIRFLOW_CTX_EXECUTION_DATE='2023-06-15T14:40:50.289983+00:00' AIRFLOW_CTX_TRY_NUMBER='1' AIRFLOW_CTX_DAG_RUN_ID='manual__2023-06-15T14:40:50.289983+00:00'
[2023-06-15T14:40:51.981+0000] {taskinstance.py:1824} ERROR - Task failed with exception
Traceback (most recent call last):
  File "/home/airflow/.local/lib/python3.7/site-packages/airflow/providers/google/cloud/operators/gcs.py", line 226, in execute
    impersonation_chain=self.impersonation_chain,
  File "/home/airflow/.local/lib/python3.7/site-packages/airflow/providers/google/cloud/hooks/gcs.py", line 165, in __init__
    impersonation_chain=impersonation_chain,
  File "/home/airflow/.local/lib/python3.7/site-packages/airflow/providers/google/common/hooks/base_google.py", line 234, in __init__
    self.extras: dict = self.get_connection(self.gcp_conn_id).extra_dejson
  File "/home/airflow/.local/lib/python3.7/site-packages/airflow/hooks/base.py", line 72, in get_connection
    conn = Connection.get_connection_from_secrets(conn_id)
  File "/home/airflow/.local/lib/python3.7/site-packages/airflow/models/connection.py", line 434, in get_connection_from_secrets
    raise AirflowNotFoundException(f"The conn_id `{conn_id}` isn't defined")
airflow.exceptions.AirflowNotFoundException: The conn_id `gcp_connection` isn't defined
[2023-06-15T14:40:51.987+0000] {taskinstance.py:1350} INFO - Marking task as FAILED. dag_id=gcs-files-dag, task_id=GCS_Files, execution_date=20230615T144050, start_date=20230615T144051, end_date=20230615T144051
[2023-06-15T14:40:51.996+0000] {standard_task_runner.py:109} ERROR - Failed to execute job 9 for task GCS_Files (The conn_id `gcp_connection` isn't defined; 558)
[2023-06-15T14:40:52.042+0000] {local_task_job_runner.py:225} INFO - Task exited with return code 1
[2023-06-15T14:40:52.061+0000] {taskinstance.py:2651} INFO - 0 downstream tasks scheduled from follow-on schedule check
