[2023-06-15T21:18:45.321+0000] {taskinstance.py:1103} INFO - Dependencies all met for dep_context=non-requeueable deps ti=<TaskInstance: gcs-files-dag.update_table manual__2023-06-15T19:23:41.146291+00:00 [queued]>
[2023-06-15T21:18:45.328+0000] {taskinstance.py:1103} INFO - Dependencies all met for dep_context=requeueable deps ti=<TaskInstance: gcs-files-dag.update_table manual__2023-06-15T19:23:41.146291+00:00 [queued]>
[2023-06-15T21:18:45.328+0000] {taskinstance.py:1308} INFO - Starting attempt 2 of 2
[2023-06-15T21:18:45.337+0000] {taskinstance.py:1327} INFO - Executing <Task(BigQueryUpdateTableOperator): update_table> on 2023-06-15 19:23:41.146291+00:00
[2023-06-15T21:18:45.343+0000] {standard_task_runner.py:57} INFO - Started process 7599 to run task
[2023-06-15T21:18:45.346+0000] {standard_task_runner.py:84} INFO - Running: ['***', 'tasks', 'run', 'gcs-files-dag', 'update_table', 'manual__2023-06-15T19:23:41.146291+00:00', '--job-id', '57', '--raw', '--subdir', 'DAGS_FOLDER/gcp_test.py', '--cfg-path', '/tmp/tmp_ddicmlx']
[2023-06-15T21:18:45.347+0000] {standard_task_runner.py:85} INFO - Job 57: Subtask update_table
[2023-06-15T21:18:45.394+0000] {task_command.py:410} INFO - Running <TaskInstance: gcs-files-dag.update_table manual__2023-06-15T19:23:41.146291+00:00 [running]> on host 6f3c5cb11aa3
[2023-06-15T21:18:45.461+0000] {taskinstance.py:1547} INFO - Exporting env vars: AIRFLOW_CTX_DAG_OWNER='***' AIRFLOW_CTX_DAG_ID='gcs-files-dag' AIRFLOW_CTX_TASK_ID='update_table' AIRFLOW_CTX_EXECUTION_DATE='2023-06-15T19:23:41.146291+00:00' AIRFLOW_CTX_TRY_NUMBER='2' AIRFLOW_CTX_DAG_RUN_ID='manual__2023-06-15T19:23:41.146291+00:00'
[2023-06-15T21:18:45.474+0000] {base.py:73} INFO - Using connection ID 'google_cloud_default' for task execution.
[2023-06-15T21:18:45.525+0000] {taskinstance.py:1824} ERROR - Task failed with exception
Traceback (most recent call last):
  File "/home/airflow/.local/lib/python3.7/site-packages/airflow/providers/google/cloud/operators/bigquery.py", line 2128, in execute
    project_id=self.project_id,
  File "/home/airflow/.local/lib/python3.7/site-packages/airflow/providers/google/common/hooks/base_google.py", line 468, in inner_wrapper
    return func(self, *args, **kwargs)
  File "/home/airflow/.local/lib/python3.7/site-packages/airflow/providers/google/cloud/hooks/bigquery.py", line 714, in update_table
    fields = fields or list(table_resource.keys())
AttributeError: 'list' object has no attribute 'keys'
[2023-06-15T21:18:45.536+0000] {taskinstance.py:1350} INFO - Marking task as FAILED. dag_id=gcs-files-dag, task_id=update_table, execution_date=20230615T192341, start_date=20230615T211845, end_date=20230615T211845
[2023-06-15T21:18:45.546+0000] {standard_task_runner.py:109} ERROR - Failed to execute job 57 for task update_table ('list' object has no attribute 'keys'; 7599)
[2023-06-15T21:18:45.599+0000] {local_task_job_runner.py:225} INFO - Task exited with return code 1
[2023-06-15T21:18:45.615+0000] {taskinstance.py:2651} INFO - 0 downstream tasks scheduled from follow-on schedule check
