[2023-06-15T21:20:44.481+0000] {taskinstance.py:1103} INFO - Dependencies all met for dep_context=non-requeueable deps ti=<TaskInstance: gcs-files-dag.update_table manual__2023-06-15T19:23:41.146291+00:00 [queued]>
[2023-06-15T21:20:44.489+0000] {taskinstance.py:1103} INFO - Dependencies all met for dep_context=requeueable deps ti=<TaskInstance: gcs-files-dag.update_table manual__2023-06-15T19:23:41.146291+00:00 [queued]>
[2023-06-15T21:20:44.490+0000] {taskinstance.py:1308} INFO - Starting attempt 4 of 4
[2023-06-15T21:20:44.500+0000] {taskinstance.py:1327} INFO - Executing <Task(BigQueryUpdateTableOperator): update_table> on 2023-06-15 19:23:41.146291+00:00
[2023-06-15T21:20:44.506+0000] {standard_task_runner.py:57} INFO - Started process 7641 to run task
[2023-06-15T21:20:44.510+0000] {standard_task_runner.py:84} INFO - Running: ['***', 'tasks', 'run', 'gcs-files-dag', 'update_table', 'manual__2023-06-15T19:23:41.146291+00:00', '--job-id', '59', '--raw', '--subdir', 'DAGS_FOLDER/gcp_test.py', '--cfg-path', '/tmp/tmpy_fdlz0t']
[2023-06-15T21:20:44.511+0000] {standard_task_runner.py:85} INFO - Job 59: Subtask update_table
[2023-06-15T21:20:44.563+0000] {task_command.py:410} INFO - Running <TaskInstance: gcs-files-dag.update_table manual__2023-06-15T19:23:41.146291+00:00 [running]> on host 6f3c5cb11aa3
[2023-06-15T21:20:44.641+0000] {taskinstance.py:1547} INFO - Exporting env vars: AIRFLOW_CTX_DAG_OWNER='***' AIRFLOW_CTX_DAG_ID='gcs-files-dag' AIRFLOW_CTX_TASK_ID='update_table' AIRFLOW_CTX_EXECUTION_DATE='2023-06-15T19:23:41.146291+00:00' AIRFLOW_CTX_TRY_NUMBER='4' AIRFLOW_CTX_DAG_RUN_ID='manual__2023-06-15T19:23:41.146291+00:00'
[2023-06-15T21:20:44.655+0000] {base.py:73} INFO - Using connection ID 'google_cloud_default' for task execution.
[2023-06-15T21:20:44.657+0000] {taskinstance.py:1824} ERROR - Task failed with exception
Traceback (most recent call last):
  File "/home/airflow/.local/lib/python3.7/site-packages/airflow/providers/google/cloud/operators/bigquery.py", line 2128, in execute
    project_id=self.project_id,
  File "/home/airflow/.local/lib/python3.7/site-packages/airflow/providers/google/common/hooks/base_google.py", line 468, in inner_wrapper
    return func(self, *args, **kwargs)
  File "/home/airflow/.local/lib/python3.7/site-packages/airflow/providers/google/cloud/hooks/bigquery.py", line 714, in update_table
    fields = fields or list(table_resource.keys())
AttributeError: 'list' object has no attribute 'keys'
[2023-06-15T21:20:44.669+0000] {taskinstance.py:1350} INFO - Marking task as FAILED. dag_id=gcs-files-dag, task_id=update_table, execution_date=20230615T192341, start_date=20230615T212044, end_date=20230615T212044
[2023-06-15T21:20:44.678+0000] {standard_task_runner.py:109} ERROR - Failed to execute job 59 for task update_table ('list' object has no attribute 'keys'; 7641)
[2023-06-15T21:20:44.724+0000] {local_task_job_runner.py:225} INFO - Task exited with return code 1
[2023-06-15T21:20:44.746+0000] {taskinstance.py:2651} INFO - 0 downstream tasks scheduled from follow-on schedule check
