[2023-06-17T16:50:12.763+0000] {taskinstance.py:1103} INFO - Dependencies all met for dep_context=non-requeueable deps ti=<TaskInstance: dbt-dag.dbt_test scheduled__2023-06-17T16:46:42.744325+00:00 [queued]>
[2023-06-17T16:50:12.771+0000] {taskinstance.py:1103} INFO - Dependencies all met for dep_context=requeueable deps ti=<TaskInstance: dbt-dag.dbt_test scheduled__2023-06-17T16:46:42.744325+00:00 [queued]>
[2023-06-17T16:50:12.772+0000] {taskinstance.py:1308} INFO - Starting attempt 2 of 2
[2023-06-17T16:50:12.783+0000] {taskinstance.py:1327} INFO - Executing <Task(DbtTestOperator): dbt_test> on 2023-06-17 16:46:42.744325+00:00
[2023-06-17T16:50:12.790+0000] {standard_task_runner.py:57} INFO - Started process 146 to run task
[2023-06-17T16:50:12.795+0000] {standard_task_runner.py:84} INFO - Running: ['***', 'tasks', 'run', 'dbt-dag', 'dbt_test', 'scheduled__2023-06-17T16:46:42.744325+00:00', '--job-id', '9', '--raw', '--subdir', 'DAGS_FOLDER/dbt_test.py', '--cfg-path', '/tmp/tmptsul3c8b']
[2023-06-17T16:50:12.799+0000] {standard_task_runner.py:85} INFO - Job 9: Subtask dbt_test
[2023-06-17T16:50:12.848+0000] {task_command.py:410} INFO - Running <TaskInstance: dbt-dag.dbt_test scheduled__2023-06-17T16:46:42.744325+00:00 [running]> on host 521d1a52fc3d
[2023-06-17T16:50:12.915+0000] {taskinstance.py:1547} INFO - Exporting env vars: AIRFLOW_CTX_DAG_OWNER='***' AIRFLOW_CTX_DAG_ID='dbt-dag' AIRFLOW_CTX_TASK_ID='dbt_test' AIRFLOW_CTX_EXECUTION_DATE='2023-06-17T16:46:42.744325+00:00' AIRFLOW_CTX_TRY_NUMBER='2' AIRFLOW_CTX_DAG_RUN_ID='scheduled__2023-06-17T16:46:42.744325+00:00'
[2023-06-17T16:50:12.917+0000] {dbt_hook.py:117} INFO - dbt test --profiles-dir /opt/***/tmp_data/dbt_bus_data/.dbt_profile/profiles.yml
[2023-06-17T16:50:12.929+0000] {dbt_hook.py:126} INFO - Output:
[2023-06-17T16:50:14.816+0000] {dbt_hook.py:130} INFO - [0m16:50:14  Running with dbt=1.5.1
[2023-06-17T16:50:14.822+0000] {dbt_hook.py:130} INFO - [0m16:50:14  Encountered an error:
[2023-06-17T16:50:14.822+0000] {dbt_hook.py:130} INFO - Runtime Error
[2023-06-17T16:50:14.823+0000] {dbt_hook.py:130} INFO -   Could not find profile named 'dbt_bus_data'
[2023-06-17T16:50:15.863+0000] {dbt_hook.py:134} INFO - Command exited with return code 2
[2023-06-17T16:50:15.877+0000] {taskinstance.py:1824} ERROR - Task failed with exception
Traceback (most recent call last):
  File "/home/airflow/.local/lib/python3.7/site-packages/airflow_dbt/operators/dbt_operator.py", line 107, in execute
    self.create_hook().run_cli('test')
  File "/home/airflow/.local/lib/python3.7/site-packages/airflow_dbt/hooks/dbt_hook.py", line 138, in run_cli
    raise AirflowException("dbt command failed")
airflow.exceptions.AirflowException: dbt command failed
[2023-06-17T16:50:15.880+0000] {taskinstance.py:1350} INFO - Marking task as FAILED. dag_id=dbt-dag, task_id=dbt_test, execution_date=20230617T164642, start_date=20230617T165012, end_date=20230617T165015
[2023-06-17T16:50:15.890+0000] {standard_task_runner.py:109} ERROR - Failed to execute job 9 for task dbt_test (dbt command failed; 146)
[2023-06-17T16:50:15.913+0000] {local_task_job_runner.py:225} INFO - Task exited with return code 1
[2023-06-17T16:50:15.930+0000] {taskinstance.py:2651} INFO - 0 downstream tasks scheduled from follow-on schedule check
