[2023-06-17T16:47:00.246+0000] {taskinstance.py:1103} INFO - Dependencies all met for dep_context=non-requeueable deps ti=<TaskInstance: dbt-dag.dbt_test manual__2023-06-17T16:46:57.694045+00:00 [queued]>
[2023-06-17T16:47:00.254+0000] {taskinstance.py:1103} INFO - Dependencies all met for dep_context=requeueable deps ti=<TaskInstance: dbt-dag.dbt_test manual__2023-06-17T16:46:57.694045+00:00 [queued]>
[2023-06-17T16:47:00.254+0000] {taskinstance.py:1308} INFO - Starting attempt 1 of 1
[2023-06-17T16:47:00.264+0000] {taskinstance.py:1327} INFO - Executing <Task(DbtTestOperator): dbt_test> on 2023-06-17 16:46:57.694045+00:00
[2023-06-17T16:47:00.269+0000] {standard_task_runner.py:57} INFO - Started process 91 to run task
[2023-06-17T16:47:00.274+0000] {standard_task_runner.py:84} INFO - Running: ['***', 'tasks', 'run', 'dbt-dag', 'dbt_test', 'manual__2023-06-17T16:46:57.694045+00:00', '--job-id', '6', '--raw', '--subdir', 'DAGS_FOLDER/dbt_test.py', '--cfg-path', '/tmp/tmp5kg2v5hx']
[2023-06-17T16:47:00.277+0000] {standard_task_runner.py:85} INFO - Job 6: Subtask dbt_test
[2023-06-17T16:47:00.348+0000] {task_command.py:410} INFO - Running <TaskInstance: dbt-dag.dbt_test manual__2023-06-17T16:46:57.694045+00:00 [running]> on host 521d1a52fc3d
[2023-06-17T16:47:00.419+0000] {taskinstance.py:1547} INFO - Exporting env vars: AIRFLOW_CTX_DAG_OWNER='***' AIRFLOW_CTX_DAG_ID='dbt-dag' AIRFLOW_CTX_TASK_ID='dbt_test' AIRFLOW_CTX_EXECUTION_DATE='2023-06-17T16:46:57.694045+00:00' AIRFLOW_CTX_TRY_NUMBER='1' AIRFLOW_CTX_DAG_RUN_ID='manual__2023-06-17T16:46:57.694045+00:00'
[2023-06-17T16:47:00.421+0000] {dbt_hook.py:117} INFO - dbt test --profiles-dir /opt/***/tmp_data/dbt_bus_data/.dbt_profile/profiles.yml
[2023-06-17T16:47:00.440+0000] {dbt_hook.py:126} INFO - Output:
[2023-06-17T16:47:03.429+0000] {dbt_hook.py:130} INFO - [0m16:47:03  Running with dbt=1.5.1
[2023-06-17T16:47:03.451+0000] {dbt_hook.py:130} INFO - [0m16:47:03  Encountered an error:
[2023-06-17T16:47:03.452+0000] {dbt_hook.py:130} INFO - Runtime Error
[2023-06-17T16:47:03.453+0000] {dbt_hook.py:130} INFO -   Could not find profile named 'dbt_bus_data'
[2023-06-17T16:47:17.129+0000] {job.py:216} ERROR - Job heartbeat got an exception
Traceback (most recent call last):
  File "/home/airflow/.local/lib/python3.7/site-packages/sqlalchemy/engine/base.py", line 3366, in _wrap_pool_connect
    return fn()
  File "/home/airflow/.local/lib/python3.7/site-packages/sqlalchemy/pool/base.py", line 327, in connect
    return _ConnectionFairy._checkout(self)
  File "/home/airflow/.local/lib/python3.7/site-packages/sqlalchemy/pool/base.py", line 894, in _checkout
    fairy = _ConnectionRecord.checkout(pool)
  File "/home/airflow/.local/lib/python3.7/site-packages/sqlalchemy/pool/base.py", line 493, in checkout
    rec = pool._do_get()
  File "/home/airflow/.local/lib/python3.7/site-packages/sqlalchemy/pool/impl.py", line 256, in _do_get
    return self._create_connection()
  File "/home/airflow/.local/lib/python3.7/site-packages/sqlalchemy/pool/base.py", line 273, in _create_connection
    return _ConnectionRecord(self)
  File "/home/airflow/.local/lib/python3.7/site-packages/sqlalchemy/pool/base.py", line 388, in __init__
    self.__connect()
  File "/home/airflow/.local/lib/python3.7/site-packages/sqlalchemy/pool/base.py", line 691, in __connect
    pool.logger.debug("Error on connect(): %s", e)
  File "/home/airflow/.local/lib/python3.7/site-packages/sqlalchemy/util/langhelpers.py", line 72, in __exit__
    with_traceback=exc_tb,
  File "/home/airflow/.local/lib/python3.7/site-packages/sqlalchemy/util/compat.py", line 211, in raise_
    raise exception
  File "/home/airflow/.local/lib/python3.7/site-packages/sqlalchemy/pool/base.py", line 686, in __connect
    self.dbapi_connection = connection = pool._invoke_creator(self)
  File "/home/airflow/.local/lib/python3.7/site-packages/sqlalchemy/engine/create.py", line 574, in connect
    return dialect.connect(*cargs, **cparams)
  File "/home/airflow/.local/lib/python3.7/site-packages/sqlalchemy/engine/default.py", line 598, in connect
    return self.dbapi.connect(*cargs, **cparams)
  File "/home/airflow/.local/lib/python3.7/site-packages/psycopg2/__init__.py", line 122, in connect
    conn = _connect(dsn, connection_factory=connection_factory, **kwasync)
psycopg2.OperationalError: could not translate host name "postgres" to address: Temporary failure in name resolution


The above exception was the direct cause of the following exception:

Traceback (most recent call last):
  File "/home/airflow/.local/lib/python3.7/site-packages/airflow/jobs/job.py", line 187, in heartbeat
    session.merge(self)
  File "/home/airflow/.local/lib/python3.7/site-packages/sqlalchemy/orm/session.py", line 3062, in merge
    _resolve_conflict_map=_resolve_conflict_map,
  File "/home/airflow/.local/lib/python3.7/site-packages/sqlalchemy/orm/session.py", line 3140, in _merge
    options=options,
  File "/home/airflow/.local/lib/python3.7/site-packages/sqlalchemy/orm/session.py", line 2861, in get
    execution_options=execution_options,
  File "/home/airflow/.local/lib/python3.7/site-packages/sqlalchemy/orm/session.py", line 2979, in _get_impl
    load_options=load_options,
  File "/home/airflow/.local/lib/python3.7/site-packages/sqlalchemy/orm/loading.py", line 534, in load_on_pk_identity
    bind_arguments=bind_arguments,
  File "/home/airflow/.local/lib/python3.7/site-packages/sqlalchemy/orm/session.py", line 1716, in execute
    conn = self._connection_for_bind(bind)
  File "/home/airflow/.local/lib/python3.7/site-packages/sqlalchemy/orm/session.py", line 1556, in _connection_for_bind
    engine, execution_options
  File "/home/airflow/.local/lib/python3.7/site-packages/sqlalchemy/orm/session.py", line 750, in _connection_for_bind
    conn = bind.connect()
  File "/home/airflow/.local/lib/python3.7/site-packages/sqlalchemy/engine/base.py", line 3320, in connect
    return self._connection_cls(self, close_with_result=close_with_result)
  File "/home/airflow/.local/lib/python3.7/site-packages/sqlalchemy/engine/base.py", line 96, in __init__
    else engine.raw_connection()
  File "/home/airflow/.local/lib/python3.7/site-packages/sqlalchemy/engine/base.py", line 3399, in raw_connection
    return self._wrap_pool_connect(self.pool.connect, _connection)
  File "/home/airflow/.local/lib/python3.7/site-packages/sqlalchemy/engine/base.py", line 3370, in _wrap_pool_connect
    e, dialect, self
  File "/home/airflow/.local/lib/python3.7/site-packages/sqlalchemy/engine/base.py", line 2204, in _handle_dbapi_exception_noconnection
    sqlalchemy_exception, with_traceback=exc_info[2], from_=e
  File "/home/airflow/.local/lib/python3.7/site-packages/sqlalchemy/util/compat.py", line 211, in raise_
    raise exception
  File "/home/airflow/.local/lib/python3.7/site-packages/sqlalchemy/engine/base.py", line 3366, in _wrap_pool_connect
    return fn()
  File "/home/airflow/.local/lib/python3.7/site-packages/sqlalchemy/pool/base.py", line 327, in connect
    return _ConnectionFairy._checkout(self)
  File "/home/airflow/.local/lib/python3.7/site-packages/sqlalchemy/pool/base.py", line 894, in _checkout
    fairy = _ConnectionRecord.checkout(pool)
  File "/home/airflow/.local/lib/python3.7/site-packages/sqlalchemy/pool/base.py", line 493, in checkout
    rec = pool._do_get()
  File "/home/airflow/.local/lib/python3.7/site-packages/sqlalchemy/pool/impl.py", line 256, in _do_get
    return self._create_connection()
  File "/home/airflow/.local/lib/python3.7/site-packages/sqlalchemy/pool/base.py", line 273, in _create_connection
    return _ConnectionRecord(self)
  File "/home/airflow/.local/lib/python3.7/site-packages/sqlalchemy/pool/base.py", line 388, in __init__
    self.__connect()
  File "/home/airflow/.local/lib/python3.7/site-packages/sqlalchemy/pool/base.py", line 691, in __connect
    pool.logger.debug("Error on connect(): %s", e)
  File "/home/airflow/.local/lib/python3.7/site-packages/sqlalchemy/util/langhelpers.py", line 72, in __exit__
    with_traceback=exc_tb,
  File "/home/airflow/.local/lib/python3.7/site-packages/sqlalchemy/util/compat.py", line 211, in raise_
    raise exception
  File "/home/airflow/.local/lib/python3.7/site-packages/sqlalchemy/pool/base.py", line 686, in __connect
    self.dbapi_connection = connection = pool._invoke_creator(self)
  File "/home/airflow/.local/lib/python3.7/site-packages/sqlalchemy/engine/create.py", line 574, in connect
    return dialect.connect(*cargs, **cparams)
  File "/home/airflow/.local/lib/python3.7/site-packages/sqlalchemy/engine/default.py", line 598, in connect
    return self.dbapi.connect(*cargs, **cparams)
  File "/home/airflow/.local/lib/python3.7/site-packages/psycopg2/__init__.py", line 122, in connect
    conn = _connect(dsn, connection_factory=connection_factory, **kwasync)
sqlalchemy.exc.OperationalError: (psycopg2.OperationalError) could not translate host name "postgres" to address: Temporary failure in name resolution

(Background on this error at: https://sqlalche.me/e/14/e3q8)
[2023-06-17T16:47:45.799+0000] {dbt_hook.py:134} INFO - Command exited with return code 2
[2023-06-17T16:47:45.853+0000] {taskinstance.py:1824} ERROR - Task failed with exception
Traceback (most recent call last):
  File "/home/airflow/.local/lib/python3.7/site-packages/airflow_dbt/operators/dbt_operator.py", line 107, in execute
    self.create_hook().run_cli('test')
  File "/home/airflow/.local/lib/python3.7/site-packages/airflow_dbt/hooks/dbt_hook.py", line 138, in run_cli
    raise AirflowException("dbt command failed")
airflow.exceptions.AirflowException: dbt command failed
[2023-06-17T16:47:45.886+0000] {taskinstance.py:1350} INFO - Marking task as FAILED. dag_id=dbt-dag, task_id=dbt_test, execution_date=20230617T164657, start_date=20230617T164700, end_date=20230617T164745
[2023-06-17T16:47:46.053+0000] {standard_task_runner.py:109} ERROR - Failed to execute job 6 for task dbt_test (dbt command failed; 91)
[2023-06-17T16:47:46.108+0000] {local_task_job_runner.py:225} INFO - Task exited with return code 1
[2023-06-17T16:47:46.171+0000] {taskinstance.py:2651} INFO - 0 downstream tasks scheduled from follow-on schedule check
