[2023-06-15T15:04:03.394+0000] {taskinstance.py:1103} INFO - Dependencies all met for dep_context=non-requeueable deps ti=<TaskInstance: gcs-files-dag.python-operator-test manual__2023-06-15T15:03:33.906044+00:00 [queued]>
[2023-06-15T15:04:03.400+0000] {taskinstance.py:1103} INFO - Dependencies all met for dep_context=requeueable deps ti=<TaskInstance: gcs-files-dag.python-operator-test manual__2023-06-15T15:03:33.906044+00:00 [queued]>
[2023-06-15T15:04:03.401+0000] {taskinstance.py:1308} INFO - Starting attempt 2 of 2
[2023-06-15T15:04:03.409+0000] {taskinstance.py:1327} INFO - Executing <Task(PythonOperator): python-operator-test> on 2023-06-15 15:03:33.906044+00:00
[2023-06-15T15:04:03.414+0000] {standard_task_runner.py:57} INFO - Started process 990 to run task
[2023-06-15T15:04:03.418+0000] {standard_task_runner.py:84} INFO - Running: ['***', 'tasks', 'run', 'gcs-files-dag', 'python-operator-test', 'manual__2023-06-15T15:03:33.906044+00:00', '--job-id', '20', '--raw', '--subdir', 'DAGS_FOLDER/gcp_test.py', '--cfg-path', '/tmp/tmpapmadizj']
[2023-06-15T15:04:03.420+0000] {standard_task_runner.py:85} INFO - Job 20: Subtask python-operator-test
[2023-06-15T15:04:03.463+0000] {task_command.py:410} INFO - Running <TaskInstance: gcs-files-dag.python-operator-test manual__2023-06-15T15:03:33.906044+00:00 [running]> on host 6f3c5cb11aa3
[2023-06-15T15:04:03.531+0000] {taskinstance.py:1547} INFO - Exporting env vars: AIRFLOW_CTX_DAG_OWNER='***' AIRFLOW_CTX_DAG_ID='gcs-files-dag' AIRFLOW_CTX_TASK_ID='python-operator-test' AIRFLOW_CTX_EXECUTION_DATE='2023-06-15T15:03:33.906044+00:00' AIRFLOW_CTX_TRY_NUMBER='2' AIRFLOW_CTX_DAG_RUN_ID='manual__2023-06-15T15:03:33.906044+00:00'
[2023-06-15T15:04:03.533+0000] {taskinstance.py:1824} ERROR - Task failed with exception
Traceback (most recent call last):
  File "/home/airflow/.local/lib/python3.7/site-packages/airflow/operators/python.py", line 181, in execute
    return_value = self.execute_callable()
  File "/home/airflow/.local/lib/python3.7/site-packages/airflow/operators/python.py", line 198, in execute_callable
    return self.python_callable(*self.op_args, **self.op_kwargs)
  File "/opt/airflow/dags/gcp_test.py", line 23, in do_work
    for i in fake_key:
TypeError: 'GCSListObjectsOperator' object is not iterable
[2023-06-15T15:04:03.546+0000] {taskinstance.py:1350} INFO - Marking task as FAILED. dag_id=gcs-files-dag, task_id=python-operator-test, execution_date=20230615T150333, start_date=20230615T150403, end_date=20230615T150403
[2023-06-15T15:04:03.554+0000] {standard_task_runner.py:109} ERROR - Failed to execute job 20 for task python-operator-test ('GCSListObjectsOperator' object is not iterable; 990)
[2023-06-15T15:04:03.591+0000] {local_task_job_runner.py:225} INFO - Task exited with return code 1
[2023-06-15T15:04:03.608+0000] {taskinstance.py:2651} INFO - 0 downstream tasks scheduled from follow-on schedule check
