[2023-06-17T17:59:47.973+0000] {taskinstance.py:1103} INFO - Dependencies all met for dep_context=non-requeueable deps ti=<TaskInstance: dbt-dag.dbt_run scheduled__2023-06-17T17:59:42.295883+00:00 [queued]>
[2023-06-17T17:59:47.979+0000] {taskinstance.py:1103} INFO - Dependencies all met for dep_context=requeueable deps ti=<TaskInstance: dbt-dag.dbt_run scheduled__2023-06-17T17:59:42.295883+00:00 [queued]>
[2023-06-17T17:59:47.980+0000] {taskinstance.py:1308} INFO - Starting attempt 1 of 1
[2023-06-17T17:59:47.988+0000] {taskinstance.py:1327} INFO - Executing <Task(DbtRunOperator): dbt_run> on 2023-06-17 17:59:42.295883+00:00
[2023-06-17T17:59:47.993+0000] {standard_task_runner.py:57} INFO - Started process 124 to run task
[2023-06-17T17:59:47.996+0000] {standard_task_runner.py:84} INFO - Running: ['***', 'tasks', 'run', 'dbt-dag', 'dbt_run', 'scheduled__2023-06-17T17:59:42.295883+00:00', '--job-id', '3', '--raw', '--subdir', 'DAGS_FOLDER/dbt_test.py', '--cfg-path', '/tmp/tmprqo1wgff']
[2023-06-17T17:59:47.998+0000] {standard_task_runner.py:85} INFO - Job 3: Subtask dbt_run
[2023-06-17T17:59:48.045+0000] {task_command.py:410} INFO - Running <TaskInstance: dbt-dag.dbt_run scheduled__2023-06-17T17:59:42.295883+00:00 [running]> on host e4b3b62346fe
[2023-06-17T17:59:48.116+0000] {taskinstance.py:1547} INFO - Exporting env vars: AIRFLOW_CTX_DAG_OWNER='***' AIRFLOW_CTX_DAG_ID='dbt-dag' AIRFLOW_CTX_TASK_ID='dbt_run' AIRFLOW_CTX_EXECUTION_DATE='2023-06-17T17:59:42.295883+00:00' AIRFLOW_CTX_TRY_NUMBER='1' AIRFLOW_CTX_DAG_RUN_ID='scheduled__2023-06-17T17:59:42.295883+00:00'
[2023-06-17T17:59:48.118+0000] {dbt_hook.py:117} INFO - dbt run --profiles-dir /opt/***/tmp_data/dbt_bus_data/.dbt_profile
[2023-06-17T17:59:48.134+0000] {taskinstance.py:1824} ERROR - Task failed with exception
Traceback (most recent call last):
  File "/home/airflow/.local/lib/python3.7/site-packages/airflow_dbt/operators/dbt_operator.py", line 98, in execute
    self.create_hook().run_cli('run')
  File "/home/airflow/.local/lib/python3.7/site-packages/airflow_dbt/hooks/dbt_hook.py", line 124, in run_cli
    close_fds=True)
  File "/usr/local/lib/python3.7/subprocess.py", line 800, in __init__
    restore_signals, start_new_session)
  File "/usr/local/lib/python3.7/subprocess.py", line 1551, in _execute_child
    raise child_exception_type(errno_num, err_msg, err_filename)
PermissionError: [Errno 13] Permission denied: 'dbt'
[2023-06-17T17:59:48.145+0000] {taskinstance.py:1350} INFO - Marking task as FAILED. dag_id=dbt-dag, task_id=dbt_run, execution_date=20230617T175942, start_date=20230617T175947, end_date=20230617T175948
[2023-06-17T17:59:48.155+0000] {standard_task_runner.py:109} ERROR - Failed to execute job 3 for task dbt_run ([Errno 13] Permission denied: 'dbt'; 124)
[2023-06-17T17:59:48.168+0000] {local_task_job_runner.py:225} INFO - Task exited with return code 1
[2023-06-17T17:59:48.186+0000] {taskinstance.py:2651} INFO - 0 downstream tasks scheduled from follow-on schedule check
