[2023-06-17T17:02:42.896+0000] {taskinstance.py:1103} INFO - Dependencies all met for dep_context=non-requeueable deps ti=<TaskInstance: dbt-dag.dbt_run manual__2023-06-17T17:02:41.638909+00:00 [queued]>
[2023-06-17T17:02:42.905+0000] {taskinstance.py:1103} INFO - Dependencies all met for dep_context=requeueable deps ti=<TaskInstance: dbt-dag.dbt_run manual__2023-06-17T17:02:41.638909+00:00 [queued]>
[2023-06-17T17:02:42.906+0000] {taskinstance.py:1308} INFO - Starting attempt 1 of 1
[2023-06-17T17:02:42.916+0000] {taskinstance.py:1327} INFO - Executing <Task(DbtRunOperator): dbt_run> on 2023-06-17 17:02:41.638909+00:00
[2023-06-17T17:02:42.923+0000] {standard_task_runner.py:57} INFO - Started process 383 to run task
[2023-06-17T17:02:42.929+0000] {standard_task_runner.py:84} INFO - Running: ['***', 'tasks', 'run', 'dbt-dag', 'dbt_run', 'manual__2023-06-17T17:02:41.638909+00:00', '--job-id', '12', '--raw', '--subdir', 'DAGS_FOLDER/dbt_test.py', '--cfg-path', '/tmp/tmpmmcrl_ej']
[2023-06-17T17:02:42.933+0000] {standard_task_runner.py:85} INFO - Job 12: Subtask dbt_run
[2023-06-17T17:02:42.995+0000] {task_command.py:410} INFO - Running <TaskInstance: dbt-dag.dbt_run manual__2023-06-17T17:02:41.638909+00:00 [running]> on host 521d1a52fc3d
[2023-06-17T17:02:43.070+0000] {taskinstance.py:1547} INFO - Exporting env vars: AIRFLOW_CTX_DAG_OWNER='***' AIRFLOW_CTX_DAG_ID='dbt-dag' AIRFLOW_CTX_TASK_ID='dbt_run' AIRFLOW_CTX_EXECUTION_DATE='2023-06-17T17:02:41.638909+00:00' AIRFLOW_CTX_TRY_NUMBER='1' AIRFLOW_CTX_DAG_RUN_ID='manual__2023-06-17T17:02:41.638909+00:00'
[2023-06-17T17:02:43.074+0000] {dbt_hook.py:117} INFO - dbt run --profiles-dir /opt/***/tmp_data/dbt_bus_data/.dbt_profile/profiles.yml
[2023-06-17T17:02:43.088+0000] {dbt_hook.py:126} INFO - Output:
[2023-06-17T17:02:45.097+0000] {dbt_hook.py:130} INFO - [0m17:02:45  Running with dbt=1.5.1
[2023-06-17T17:02:45.103+0000] {dbt_hook.py:130} INFO - [0m17:02:45  Encountered an error:
[2023-06-17T17:02:45.103+0000] {dbt_hook.py:130} INFO - Runtime Error
[2023-06-17T17:02:45.104+0000] {dbt_hook.py:130} INFO -   Could not find profile named 'dbt_bus_data'
[2023-06-17T17:02:46.032+0000] {dbt_hook.py:134} INFO - Command exited with return code 2
[2023-06-17T17:02:46.048+0000] {taskinstance.py:1824} ERROR - Task failed with exception
Traceback (most recent call last):
  File "/home/airflow/.local/lib/python3.7/site-packages/airflow_dbt/operators/dbt_operator.py", line 98, in execute
    self.create_hook().run_cli('run')
  File "/home/airflow/.local/lib/python3.7/site-packages/airflow_dbt/hooks/dbt_hook.py", line 138, in run_cli
    raise AirflowException("dbt command failed")
airflow.exceptions.AirflowException: dbt command failed
[2023-06-17T17:02:46.052+0000] {taskinstance.py:1350} INFO - Marking task as FAILED. dag_id=dbt-dag, task_id=dbt_run, execution_date=20230617T170241, start_date=20230617T170242, end_date=20230617T170246
[2023-06-17T17:02:46.062+0000] {standard_task_runner.py:109} ERROR - Failed to execute job 12 for task dbt_run (dbt command failed; 383)
[2023-06-17T17:02:46.088+0000] {local_task_job_runner.py:225} INFO - Task exited with return code 1
[2023-06-17T17:02:46.106+0000] {taskinstance.py:2651} INFO - 0 downstream tasks scheduled from follow-on schedule check
