[2023-06-19T17:12:02.936+0000] {taskinstance.py:1103} INFO - Dependencies all met for dep_context=non-requeueable deps ti=<TaskInstance: running-buses-gcs-files-dag.delete_table_running_buses manual__2023-06-19T17:12:01.706745+00:00 [queued]>
[2023-06-19T17:12:02.941+0000] {taskinstance.py:1103} INFO - Dependencies all met for dep_context=requeueable deps ti=<TaskInstance: running-buses-gcs-files-dag.delete_table_running_buses manual__2023-06-19T17:12:01.706745+00:00 [queued]>
[2023-06-19T17:12:02.942+0000] {taskinstance.py:1308} INFO - Starting attempt 1 of 1
[2023-06-19T17:12:02.951+0000] {taskinstance.py:1327} INFO - Executing <Task(BigQueryDeleteTableOperator): delete_table_running_buses> on 2023-06-19 17:12:01.706745+00:00
[2023-06-19T17:12:02.956+0000] {standard_task_runner.py:57} INFO - Started process 157 to run task
[2023-06-19T17:12:02.961+0000] {standard_task_runner.py:84} INFO - Running: ['***', 'tasks', 'run', 'running-buses-gcs-files-dag', 'delete_table_running_buses', 'manual__2023-06-19T17:12:01.706745+00:00', '--job-id', '112', '--raw', '--subdir', 'DAGS_FOLDER/running_buses_dag.py', '--cfg-path', '/tmp/tmpv7q36nt8']
[2023-06-19T17:12:02.962+0000] {standard_task_runner.py:85} INFO - Job 112: Subtask delete_table_running_buses
[2023-06-19T17:12:03.031+0000] {task_command.py:410} INFO - Running <TaskInstance: running-buses-gcs-files-dag.delete_table_running_buses manual__2023-06-19T17:12:01.706745+00:00 [running]> on host 6bba1fead03c
[2023-06-19T17:12:03.102+0000] {taskinstance.py:1545} INFO - Exporting env vars: AIRFLOW_CTX_DAG_OWNER='***' AIRFLOW_CTX_DAG_ID='running-buses-gcs-files-dag' AIRFLOW_CTX_TASK_ID='delete_table_running_buses' AIRFLOW_CTX_EXECUTION_DATE='2023-06-19T17:12:01.706745+00:00' AIRFLOW_CTX_TRY_NUMBER='1' AIRFLOW_CTX_DAG_RUN_ID='manual__2023-06-19T17:12:01.706745+00:00'
[2023-06-19T17:12:03.106+0000] {bigquery.py:2323} INFO - Deleting: bus-data-389717.dbt_busdata_stag.external_table_running_buses
[2023-06-19T17:12:03.115+0000] {base.py:73} INFO - Using connection ID 'google_cloud_default' for task execution.
[2023-06-19T17:12:03.117+0000] {taskinstance.py:1824} ERROR - Task failed with exception
Traceback (most recent call last):
  File "/home/airflow/.local/lib/python3.11/site-packages/airflow/providers/google/cloud/operators/bigquery.py", line 2329, in execute
    hook.delete_table(table_id=self.deletion_dataset_table, not_found_ok=self.ignore_if_missing)
  File "/home/airflow/.local/lib/python3.11/site-packages/airflow/providers/google/common/hooks/base_google.py", line 461, in inner_wrapper
    kwargs["project_id"] = self.project_id
                           ^^^^^^^^^^^^^^^
  File "/home/airflow/.local/lib/python3.11/site-packages/airflow/providers/google/common/hooks/base_google.py", line 348, in project_id
    _, project_id = self.get_credentials_and_project_id()
                    ^^^^^^^^^^^^^^^^^^^^^^^^^^^^^^^^^^^^^
  File "/home/airflow/.local/lib/python3.11/site-packages/airflow/providers/google/common/hooks/base_google.py", line 259, in get_credentials_and_project_id
    credentials, project_id = get_credentials_and_project_id(
                              ^^^^^^^^^^^^^^^^^^^^^^^^^^^^^^^
  File "/home/airflow/.local/lib/python3.11/site-packages/airflow/providers/google/cloud/utils/credentials_provider.py", line 332, in get_credentials_and_project_id
    return _CredentialProvider(*args, **kwargs).get_credentials_and_project()
           ^^^^^^^^^^^^^^^^^^^^^^^^^^^^^^^^^^^^^^^^^^^^^^^^^^^^^^^^^^^^^^^^^^
  File "/home/airflow/.local/lib/python3.11/site-packages/airflow/providers/google/cloud/utils/credentials_provider.py", line 231, in get_credentials_and_project
    credentials, project_id = self._get_credentials_using_key_path()
                              ^^^^^^^^^^^^^^^^^^^^^^^^^^^^^^^^^^^^^^
  File "/home/airflow/.local/lib/python3.11/site-packages/airflow/providers/google/cloud/utils/credentials_provider.py", line 280, in _get_credentials_using_key_path
    credentials = google.oauth2.service_account.Credentials.from_service_account_file(
                  ^^^^^^^^^^^^^^^^^^^^^^^^^^^^^^^^^^^^^^^^^^^^^^^^^^^^^^^^^^^^^^^^^^^^
  File "/home/airflow/.local/lib/python3.11/site-packages/google/oauth2/service_account.py", line 256, in from_service_account_file
    info, signer = _service_account_info.from_filename(
                   ^^^^^^^^^^^^^^^^^^^^^^^^^^^^^^^^^^^^
  File "/home/airflow/.local/lib/python3.11/site-packages/google/auth/_service_account_info.py", line 80, in from_filename
    with io.open(filename, "r", encoding="utf-8") as json_file:
         ^^^^^^^^^^^^^^^^^^^^^^^^^^^^^^^^^^^^^^^^
FileNotFoundError: [Errno 2] No such file or directory: '/opt/airflow/tmp_data/.google/bus-data-389717-3c31a20fe458.json'
[2023-06-19T17:12:03.130+0000] {taskinstance.py:1345} INFO - Marking task as FAILED. dag_id=running-buses-gcs-files-dag, task_id=delete_table_running_buses, execution_date=20230619T171201, start_date=20230619T171202, end_date=20230619T171203
[2023-06-19T17:12:03.138+0000] {standard_task_runner.py:104} ERROR - Failed to execute job 112 for task delete_table_running_buses ([Errno 2] No such file or directory: '/opt/airflow/tmp_data/.google/bus-data-389717-3c31a20fe458.json'; 157)
[2023-06-19T17:12:03.178+0000] {local_task_job_runner.py:225} INFO - Task exited with return code 1
[2023-06-19T17:12:03.192+0000] {taskinstance.py:2653} INFO - 0 downstream tasks scheduled from follow-on schedule check
