[2023-06-15T22:52:46.554+0000] {taskinstance.py:1103} INFO - Dependencies all met for dep_context=non-requeueable deps ti=<TaskInstance: gcs-files-dag.delete_table manual__2023-06-15T22:52:44.992955+00:00 [queued]>
[2023-06-15T22:52:46.562+0000] {taskinstance.py:1103} INFO - Dependencies all met for dep_context=requeueable deps ti=<TaskInstance: gcs-files-dag.delete_table manual__2023-06-15T22:52:44.992955+00:00 [queued]>
[2023-06-15T22:52:46.563+0000] {taskinstance.py:1308} INFO - Starting attempt 1 of 1
[2023-06-15T22:52:46.574+0000] {taskinstance.py:1327} INFO - Executing <Task(BigQueryDeleteTableOperator): delete_table> on 2023-06-15 22:52:44.992955+00:00
[2023-06-15T22:52:46.580+0000] {standard_task_runner.py:57} INFO - Started process 9251 to run task
[2023-06-15T22:52:46.585+0000] {standard_task_runner.py:84} INFO - Running: ['***', 'tasks', 'run', 'gcs-files-dag', 'delete_table', 'manual__2023-06-15T22:52:44.992955+00:00', '--job-id', '66', '--raw', '--subdir', 'DAGS_FOLDER/gcp_test.py', '--cfg-path', '/tmp/tmpnwp_hhm0']
[2023-06-15T22:52:46.586+0000] {standard_task_runner.py:85} INFO - Job 66: Subtask delete_table
[2023-06-15T22:52:46.651+0000] {task_command.py:410} INFO - Running <TaskInstance: gcs-files-dag.delete_table manual__2023-06-15T22:52:44.992955+00:00 [running]> on host 6f3c5cb11aa3
[2023-06-15T22:52:46.729+0000] {taskinstance.py:1547} INFO - Exporting env vars: AIRFLOW_CTX_DAG_OWNER='***' AIRFLOW_CTX_DAG_ID='gcs-files-dag' AIRFLOW_CTX_TASK_ID='delete_table' AIRFLOW_CTX_EXECUTION_DATE='2023-06-15T22:52:44.992955+00:00' AIRFLOW_CTX_TRY_NUMBER='1' AIRFLOW_CTX_DAG_RUN_ID='manual__2023-06-15T22:52:44.992955+00:00'
[2023-06-15T22:52:46.733+0000] {bigquery.py:2274} INFO - Deleting: bus-data-389717.dbt_busdata_stag.externalx
[2023-06-15T22:52:46.742+0000] {base.py:73} INFO - Using connection ID 'google_cloud_default' for task execution.
[2023-06-15T22:52:47.197+0000] {taskinstance.py:1824} ERROR - Task failed with exception
Traceback (most recent call last):
  File "/home/airflow/.local/lib/python3.7/site-packages/airflow/providers/google/cloud/operators/bigquery.py", line 2280, in execute
    hook.delete_table(table_id=self.deletion_dataset_table, not_found_ok=self.ignore_if_missing)
  File "/home/airflow/.local/lib/python3.7/site-packages/airflow/providers/google/common/hooks/base_google.py", line 468, in inner_wrapper
    return func(self, *args, **kwargs)
  File "/home/airflow/.local/lib/python3.7/site-packages/airflow/providers/google/cloud/hooks/bigquery.py", line 1194, in delete_table
    not_found_ok=not_found_ok,
  File "/home/airflow/.local/lib/python3.7/site-packages/google/cloud/bigquery/client.py", line 1823, in delete_table
    timeout=timeout,
  File "/home/airflow/.local/lib/python3.7/site-packages/google/cloud/bigquery/client.py", line 782, in _call_api
    return call()
  File "/home/airflow/.local/lib/python3.7/site-packages/google/api_core/retry.py", line 288, in retry_wrapped_func
    on_error=on_error,
  File "/home/airflow/.local/lib/python3.7/site-packages/google/api_core/retry.py", line 190, in retry_target
    return target()
  File "/home/airflow/.local/lib/python3.7/site-packages/google/cloud/_http/__init__.py", line 494, in api_request
    raise exceptions.from_http_response(response)
google.api_core.exceptions.NotFound: 404 DELETE https://bigquery.googleapis.com/bigquery/v2/projects/bus-data-389717/datasets/dbt_busdata_stag/tables/externalx?prettyPrint=false: Not found: Table bus-data-389717:dbt_busdata_stag.externalx
[2023-06-15T22:52:47.232+0000] {taskinstance.py:1350} INFO - Marking task as FAILED. dag_id=gcs-files-dag, task_id=delete_table, execution_date=20230615T225244, start_date=20230615T225246, end_date=20230615T225247
[2023-06-15T22:52:47.242+0000] {standard_task_runner.py:109} ERROR - Failed to execute job 66 for task delete_table (404 DELETE https://bigquery.googleapis.com/bigquery/v2/projects/bus-data-389717/datasets/dbt_busdata_stag/tables/externalx?prettyPrint=false: Not found: Table bus-data-389717:dbt_busdata_stag.externalx; 9251)
[2023-06-15T22:52:47.281+0000] {local_task_job_runner.py:225} INFO - Task exited with return code 1
[2023-06-15T22:52:47.307+0000] {taskinstance.py:2651} INFO - 0 downstream tasks scheduled from follow-on schedule check
